[
  {
    "id" : "fe123e9e-a06e-4845-b705-a3cbdf118fa2",
    "prId" : 5341,
    "prUrl" : "https://github.com/apache/kafka/pull/5341#pullrequestreview-135098733",
    "prSource" : "GitHub",
    "comments" : [
      {
        "id" : "fd7dafff-7eed-4ef1-9d2b-1ac46b2aca87",
        "parentId" : null,
        "authorId" : "442b5138-0781-4001-8ac5-0593f2136d1c",
        "body" : "If we get an exception, should we fail the test?",
        "createdAt" : "2018-07-06T16:11:49Z",
        "updatedAt" : "2018-07-06T17:35:26Z",
        "lastEditedBy" : "442b5138-0781-4001-8ac5-0593f2136d1c",
        "tags" : [
        ]
      },
      {
        "id" : "2648f485-7cc2-4049-a379-7770db1f97e3",
        "parentId" : "fd7dafff-7eed-4ef1-9d2b-1ac46b2aca87",
        "authorId" : "b4936a15-698a-496e-85a1-b1e229b4986b",
        "body" : "The test fails if there is an exception since it verifies that the task is still running.",
        "createdAt" : "2018-07-06T17:36:07Z",
        "updatedAt" : "2018-07-06T17:36:07Z",
        "lastEditedBy" : "b4936a15-698a-496e-85a1-b1e229b4986b",
        "tags" : [
        ]
      }
    ],
    "commit" : "44503e88b1cec00d1de51c33f8082846ef1a8a7c",
    "line" : 153,
    "diffHunk" : "@@ -1,1 +729,733 @@                }\n            } catch (Throwable t) {\n                log.error(\"Metric {} failed with exception\", opName, t);\n            }\n        }"
  }
]