[
  {
    "id" : "be96a575-e702-4a2e-96de-2283f46cb1c5",
    "prId" : 42074,
    "prUrl" : "https://github.com/tensorflow/tensorflow/pull/42074#pullrequestreview-465470984",
    "prSource" : "GitHub",
    "comments" : [
      {
        "id" : "25155fe1-7195-41e3-9c30-1b56aca22fd2",
        "parentId" : null,
        "authorId" : "d9857ae4-1f12-46ba-8f0b-0bc35ebb4bfa",
        "body" : "any reason to have atol here? I think the out and out2 should be identical.",
        "createdAt" : "2020-08-11T21:09:18Z",
        "updatedAt" : "2020-08-11T22:52:09Z",
        "lastEditedBy" : "d9857ae4-1f12-46ba-8f0b-0bc35ebb4bfa",
        "tags" : [
        ]
      },
      {
        "id" : "677e5bfd-d615-490d-8f91-6d09cc592b67",
        "parentId" : "25155fe1-7195-41e3-9c30-1b56aca22fd2",
        "authorId" : "822f3bb9-f3a0-4ab5-bbb6-bd10cf387569",
        "body" : "The existing tests have this atol. I assumed it is there in case there is any inaccuracy when saving/loading?  So I just did the same thing as the others. ",
        "createdAt" : "2020-08-11T22:26:59Z",
        "updatedAt" : "2020-08-11T22:52:09Z",
        "lastEditedBy" : "822f3bb9-f3a0-4ab5-bbb6-bd10cf387569",
        "tags" : [
        ]
      }
    ],
    "commit" : "c09eabcd28667c81e86a2cbafb5a68c03186e038",
    "line" : 25,
    "diffHunk" : "@@ -1,1 +752,756 @@\n      out2 = new_model.predict(x)\n      self.assertAllClose(out, out2, atol=1e-05)\n\n  def test_model_raise_exception_with_failed_saving(self):"
  },
  {
    "id" : "91642b9d-85b1-4046-a689-33f12a8fea94",
    "prId" : 42074,
    "prUrl" : "https://github.com/tensorflow/tensorflow/pull/42074#pullrequestreview-465568585",
    "prSource" : "GitHub",
    "comments" : [
      {
        "id" : "f5f86249-7b84-459c-ad8f-eaa956f340a7",
        "parentId" : null,
        "authorId" : "d9857ae4-1f12-46ba-8f0b-0bc35ebb4bfa",
        "body" : "Its bit weird that the file object created is not used at all here, is this h5 file context needed?",
        "createdAt" : "2020-08-12T02:54:36Z",
        "updatedAt" : "2020-08-12T02:54:36Z",
        "lastEditedBy" : "d9857ae4-1f12-46ba-8f0b-0bc35ebb4bfa",
        "tags" : [
        ]
      },
      {
        "id" : "b3647f0c-d4f8-40b3-aaea-4fc7c01f513d",
        "parentId" : "f5f86249-7b84-459c-ad8f-eaa956f340a7",
        "authorId" : "822f3bb9-f3a0-4ab5-bbb6-bd10cf387569",
        "body" : "This object keeps the file open, so that model saving on the same path will error out, in order to test the exception is thrown. Should I add a comment to explain?",
        "createdAt" : "2020-08-12T03:23:53Z",
        "updatedAt" : "2020-08-12T03:23:53Z",
        "lastEditedBy" : "822f3bb9-f3a0-4ab5-bbb6-bd10cf387569",
        "tags" : [
        ]
      },
      {
        "id" : "8ad5ab53-76d5-466e-99bf-a8967101d8bd",
        "parentId" : "f5f86249-7b84-459c-ad8f-eaa956f340a7",
        "authorId" : "d9857ae4-1f12-46ba-8f0b-0bc35ebb4bfa",
        "body" : "oh, that's fine.",
        "createdAt" : "2020-08-12T03:35:55Z",
        "updatedAt" : "2020-08-12T03:35:56Z",
        "lastEditedBy" : "d9857ae4-1f12-46ba-8f0b-0bc35ebb4bfa",
        "tags" : [
        ]
      }
    ],
    "commit" : "c09eabcd28667c81e86a2cbafb5a68c03186e038",
    "line" : 41,
    "diffHunk" : "@@ -1,1 +768,772 @@\n      with self.assertRaisesRegex(OSError, 'Unable to create file'):\n        with h5py.File(saved_model_path, 'w'):\n          keras.models.save_model(model, saved_model_path)\n"
  }
]