[
  {
    "id" : "ebaebcf3-ea69-4cdb-8015-edfb0d57134c",
    "prId" : 55532,
    "prUrl" : "https://github.com/ansible/ansible/pull/55532#pullrequestreview-230370719",
    "prSource" : "GitHub",
    "comments" : [
      {
        "id" : "2b87c81c-21f0-4f6b-b9b3-39962d46fa71",
        "parentId" : null,
        "authorId" : "838eb58c-0fa8-4742-994f-a407c7183e57",
        "body" : "Note for the next time you need to do some work in here: rather than use a dummy variable, it's more idiomatic to just not assign the exception to a variable:\r\n``` suggestion\r\nexcept Exception:\r\n```",
        "createdAt" : "2019-04-23T18:31:14Z",
        "updatedAt" : "2019-04-23T18:31:14Z",
        "lastEditedBy" : "838eb58c-0fa8-4742-994f-a407c7183e57",
        "tags" : [
        ]
      },
      {
        "id" : "bcd7053f-a5cd-4ad8-b0eb-0c550493acb5",
        "parentId" : "2b87c81c-21f0-4f6b-b9b3-39962d46fa71",
        "authorId" : "57db1e2a-9c1c-4c08-b54f-9731aff18e36",
        "body" : "Does pylint/pep8 accept this style?",
        "createdAt" : "2019-04-23T18:34:28Z",
        "updatedAt" : "2019-04-23T18:34:28Z",
        "lastEditedBy" : "57db1e2a-9c1c-4c08-b54f-9731aff18e36",
        "tags" : [
        ]
      },
      {
        "id" : "97297ee9-c3e4-4e7d-8755-0e2b532205e0",
        "parentId" : "2b87c81c-21f0-4f6b-b9b3-39962d46fa71",
        "authorId" : "d10c46ef-3d4c-4766-bd09-d27ec4674a84",
        "body" : "@abadger thanks! I'll try to remember that :)\r\n@MarkusTeufelberger it seems to be OK, considering that a lot of modules do that.",
        "createdAt" : "2019-04-23T18:50:31Z",
        "updatedAt" : "2019-04-23T18:50:31Z",
        "lastEditedBy" : "d10c46ef-3d4c-4766-bd09-d27ec4674a84",
        "tags" : [
        ]
      },
      {
        "id" : "370632d4-e93f-422a-a168-77ce044bb5d0",
        "parentId" : "2b87c81c-21f0-4f6b-b9b3-39962d46fa71",
        "authorId" : "838eb58c-0fa8-4742-994f-a407c7183e57",
        "body" : "Yep.  In default configurations, pylint will complain that Exception is caught (exception too broad).  It does not complain that the exception is not assigned to a variable. \r\n\r\n(Our configuration of pylint allows catching Exception.  Mostly because it would be extremely time consuming for us to clean that up... Having to evaluate every usage of Exception to see if it is valid or should be replaced with something more targeted)",
        "createdAt" : "2019-04-24T21:40:41Z",
        "updatedAt" : "2019-04-24T21:40:41Z",
        "lastEditedBy" : "838eb58c-0fa8-4742-994f-a407c7183e57",
        "tags" : [
        ]
      }
    ],
    "commit" : "d4485ceb6f2353b65e32600acc0a75fae64aba43",
    "line" : 13,
    "diffHunk" : "@@ -1,1 +48,52 @@    if HAS_CURRENT_CRYPTOGRAPHY:\n        _cryptography_backend = cryptography.hazmat.backends.default_backend()\nexcept Exception as dummy:\n    HAS_CURRENT_CRYPTOGRAPHY = False\n"
  }
]